<?xml version="1.0" ?>
<!-- =================================================================================== -->
<!-- |    This document was autogenerated by xacro from rtop.urdf.xacro                | -->
<!-- |    EDITING THIS FILE BY HAND IS NOT RECOMMENDED                                 | -->
<!-- =================================================================================== -->
<robot name="rtop">
  <!-- Base link (body) -->
  <link name="base">
    <inertial>
      <origin rpy="1.5708 0.0 1.5708" xyz="0.0 0.0 0.0"/>
      <mass value="10.0"/>
      <inertia ixx="1.0" ixy="0" ixz="0" iyy="1.0" iyz="0" izz="1.0"/>
    </inertial>
    <!-- TRONCO -->
    <visual name="base_visual">
      <origin rpy="1.5708 0.0 1.5708" xyz="0.0 0.0 1.0"/>
      <geometry>
        <box size="0.30 1.0 0.25"/>
      </geometry>
    </visual>
    <!-- HOMBROS -->
    <visual name="base_visual_hombros">
      <origin rpy="1.5708 0.0 1.5708" xyz="0.0 0.0 1.0"/>
      <geometry>
        <box size="0.8 0.12 0.10"/>
      </geometry>
    </visual>
    <!-- CABEZA -->
    <visual name="base_visual_cabeza">
      <origin rpy="1.5708 0.0 1.5708" xyz="0.0 0.0 1.65"/>
      <geometry>
        <sphere radius="0.125"/>
      </geometry>
    </visual>
    <collision name="base_collision">
      <origin rpy="1.5708 0.0 1.5708" xyz="0.0 0.0 1.0"/>
      <geometry>
        <box size="0.30 1.0 0.25"/>
      </geometry>
    </collision>
    <!-- HOMBROS -->
    <collision name="base_collision_hombros">
      <origin rpy="1.5708 0.0 1.5708" xyz="0.0 0.0 1.0"/>
      <geometry>
        <box size="0.8 0.12 0.10"/>
      </geometry>
    </collision>
    <!-- CABEZA -->
    <collision name="base_collision_cabeza">
      <origin rpy="1.5708 0.0 1.5708" xyz="0.0 0.0 1.65"/>
      <geometry>
        <sphere radius="0.125"/>
      </geometry>
    </collision>
  </link>
  <!-- Top camera link -->
  <link name="top_camera">
    <inertial>
      <origin rpy="0.0 0.0 0.0" xyz="0.0 0.0 0.0"/>
      <mass value="0.5"/>
      <inertia ixx="0.001" ixy="0" ixz="0" iyy="0.001" iyz="0" izz="0.001"/>
    </inertial>
    <visual name="top_camera_visual">
      <origin rpy="0.0 0.0 0.0" xyz="0.0 0.0 0.0"/>
      <geometry>
        <mesh filename="package://rtop_description/meshes/top_camera.obj"/>
      </geometry>
    </visual>
    <collision name="top_camera_collision">
      <origin rpy="0.0 0.0 0.0" xyz="0.0 0.0 0.0"/>
      <geometry>
        <mesh filename="package://rtop_description/meshes/top_camera.obj"/>
      </geometry>
    </collision>
  </link>
  <!-- Joint from base to top camera -->
  <joint name="base_to_top_camera" type="fixed">
    <parent link="base"/>
    <child link="top_camera"/>
    <origin rpy="2.84489 0.0 1.5708" xyz="0.0865 0.0 1.77"/>
  </joint>
  <!-- World link -->
  <link name="world">
    <inertial>
      <origin rpy="0.0 0.0 0.0" xyz="0.0 0.0 0.0"/>
      <mass value="0.0"/>
      <inertia ixx="0.0" ixy="0" ixz="0" iyy="0.0" iyz="0" izz="0.0"/>
    </inertial>
  </link>
  <!-- Joint from world to base -->
  <joint name="world_to_base" type="fixed">
    <parent link="world"/>
    <child link="base"/>
    <origin rpy="0.0 0.0 0.0" xyz="0.0 0.0 0.0"/>
  </joint>
  <!-- Arm base link -->
  <link name="left_arm">
    <inertial>
      <origin rpy="0.0 0.0 0.0" xyz="0.0 0.0 0.026"/>
      <mass value="0.21895644158459424"/>
      <inertia ixx="0.00013879124248906134" ixy="0" ixz="0" iyy="0.00013879124248906134" iyz="0" izz="0.00010282878735692499"/>
    </inertial>
    <visual name="left_model2">
      <origin rpy="1.5701130102263443 0.005344186766801151 -3.1414365496107033" xyz="-2.0738360577213484e-05 2.041311002275178e-05 0.01154286287615687"/>
      <geometry>
        <mesh filename="package://yam_arm_description/meshes/converted_model2_808080ff.obj"/>
      </geometry>
    </visual>
    <collision name="left_model2_collision">
      <origin rpy="1.5701130102263443 0.005344186766801151 -3.1414365496107033" xyz="-2.0738360577213484e-05 2.041311002275178e-05 0.01154286287615687"/>
      <geometry>
        <mesh filename="package://yam_arm_description/meshes/converted_model2_808080ff.obj"/>
      </geometry>
    </collision>
  </link>
  <joint name="left_parent2arm_fixed" type="fixed">
    <parent link="base"/>
    <child link="left_arm"/>
    <origin rpy="0.0 0.0 0.0" xyz="0.0 0.305 1.0"/>
  </joint>
  <!-- Link 1 -->
  <link name="left_link_1">
    <inertial>
      <origin rpy="1.6743480392523338 -0.6015439689011491 1.5666873963753192" xyz="-0.00192861 -0.00795735 0.0208176"/>
      <mass value="0.12415"/>
      <inertia ixx="0.000180751" ixy="0" ixz="0" iyy="0.000145532" iyz="0" izz="5.89179e-05"/>
    </inertial>
    <visual name="left_model2__2">
      <origin rpy="1.5650454550240567 -0.6317582807873867 1.5710673633815686" xyz="0.0007117901440024366 -0.008267794027987337 0.022250179687008112"/>
      <geometry>
        <mesh filename="package://yam_arm_description/meshes/converted_model2__2_808080ff.obj"/>
      </geometry>
    </visual>
    <collision name="left_model2__2_collision">
      <origin rpy="1.5650454550240567 -0.6317582807873867 1.5710673633815686" xyz="0.0007117901440024366 -0.008267794027987337 0.022250179687008112"/>
      <geometry>
        <mesh filename="package://yam_arm_description/meshes/converted_model2__2_808080ff.obj"/>
      </geometry>
    </collision>
  </link>
  <link name="left_joint1_link">
    <inertial>
      <origin rpy="0.0 0.0 0.0" xyz="0.0 0.0 0.0"/>
      <mass value="0.001"/>
      <inertia ixx="1e-09" ixy="0" ixz="0" iyy="1e-09" iyz="0" izz="1e-09"/>
    </inertial>
  </link>
  <joint name="left_joint1" type="revolute">
    <parent link="left_arm"/>
    <child link="left_joint1_link"/>
    <origin rpy="0.0 0.0 1.5707963267948963" xyz="0.0 0.0 0.0631"/>
    <axis xyz="0.0 0.0 1.0"/>
    <limit effort="100" lower="-2.61799" upper="3.05433" velocity="100"/>
  </joint>
  <joint name="left_joint1_offset" type="fixed">
    <parent link="left_joint1_link"/>
    <child link="left_link_1"/>
    <origin rpy="0.0 0.0 0.0" xyz="-0.0 -0.0 -0.0"/>
  </joint>
  <!-- Link 2 -->
  <link name="left_link_2">
    <inertial>
      <origin rpy="1.5707963267948966 0.0 1.5707963267948966" xyz="0.132008 2.10599e-06 0.000293073"/>
      <mass value="1.24434"/>
      <inertia ixx="0.0121902" ixy="0" ixz="0" iyy="0.0121318" iyz="0" izz="0.000683304"/>
    </inertial>
    <visual name="left_model2__3">
      <origin rpy="0.0012886015838013758 0.0 1.5707963267948966" xyz="0.26007948449650414 2.5977632368834325e-07 0.00022869283697025413"/>
      <geometry>
        <mesh filename="package://yam_arm_description/meshes/converted_model2__3_808080ff.obj"/>
      </geometry>
    </visual>
    <collision name="left_model2__3_collision">
      <origin rpy="0.0012886015838013758 0.0 1.5707963267948966" xyz="0.26007948449650414 2.5977632368834325e-07 0.00022869283697025413"/>
      <geometry>
        <mesh filename="package://yam_arm_description/meshes/converted_model2__3_808080ff.obj"/>
      </geometry>
    </collision>
    <visual name="left_model2__4">
      <origin rpy="-0.0012886020855807743 0.0 1.5707963267948966" xyz="0.003920561027152974 2.5977629421192194e-07 0.00022869282878015162"/>
      <geometry>
        <mesh filename="package://yam_arm_description/meshes/converted_model2__4_808080ff.obj"/>
      </geometry>
    </visual>
    <collision name="left_model2__4_collision">
      <origin rpy="-0.0012886020855807743 0.0 1.5707963267948966" xyz="0.003920561027152974 2.5977629421192194e-07 0.00022869282878015162"/>
      <geometry>
        <mesh filename="package://yam_arm_description/meshes/converted_model2__4_808080ff.obj"/>
      </geometry>
    </collision>
    <visual name="left_model2__5">
      <origin rpy="1.5720341600620127 -1.5679213575591051 -1.5720413321413815" xyz="0.1320117461361114 -1.306943646950387e-05 9.079293692478702e-08"/>
      <geometry>
        <mesh filename="package://yam_arm_description/meshes/converted_model2__5_808080ff.obj"/>
      </geometry>
    </visual>
    <collision name="left_model2__5_collision">
      <origin rpy="1.5720341600620127 -1.5679213575591051 -1.5720413321413815" xyz="0.1320117461361114 -1.306943646950387e-05 9.079293692478702e-08"/>
      <geometry>
        <mesh filename="package://yam_arm_description/meshes/converted_model2__5_808080ff.obj"/>
      </geometry>
    </collision>
  </link>
  <link name="left_joint2_link">
    <inertial>
      <origin rpy="0.0 0.0 0.0" xyz="0.0 0.0 0.0"/>
      <mass value="0.001"/>
      <inertia ixx="1e-09" ixy="0" ixz="0" iyy="1e-09" iyz="0" izz="1e-09"/>
    </inertial>
  </link>
  <joint name="left_joint2" type="revolute">
    <parent link="left_link_1"/>
    <child link="left_joint2_link"/>
    <origin rpy="1.5707963267948966 0.0 1.5707963267948966" xyz="2.5e-05 -0.02 0.0409"/>
    <axis xyz="0.0 0.0 1.0"/>
    <limit effort="300" lower="-1.0e-03" upper="3.66519" velocity="100"/>
  </joint>
  <joint name="left_joint2_offset" type="fixed">
    <parent link="left_joint2_link"/>
    <child link="left_link_2"/>
    <origin rpy="0.0 0.0 0.0" xyz="-0.0 -0.0 -0.0"/>
  </joint>
  <!-- Link 3 -->
  <link name="left_link_3">
    <inertial>
      <origin rpy="1.5707963267948966 0.0 1.5707963267948966" xyz="-0.121816 -0.054846 -0.000111108"/>
      <mass value="0.853698"/>
      <inertia ixx="0.00699732" ixy="0" ixz="0" iyy="0.00696112" iyz="0" izz="0.000788244"/>
    </inertial>
    <visual name="left_model2__6">
      <origin rpy="3.0364915071378875 0.0 -1.5707963267948968" xyz="-0.24063976713274154 -0.059999782142154706 -0.003760273578300405"/>
      <geometry>
        <mesh filename="package://yam_arm_description/meshes/converted_model2__6_808080ff.obj"/>
      </geometry>
    </visual>
    <collision name="left_model2__6_collision">
      <origin rpy="3.0364915071378875 0.0 -1.5707963267948968" xyz="-0.24063976713274154 -0.059999782142154706 -0.003760273578300405"/>
      <geometry>
        <mesh filename="package://yam_arm_description/meshes/converted_model2__6_808080ff.obj"/>
      </geometry>
    </collision>
    <visual name="left_model2__7">
      <origin rpy="-2.87879006743723 1.4720957652931421 1.6013719605643306" xyz="-0.007710009148021196 -0.03486048010433765 0.0347071645682882"/>
      <geometry>
        <mesh filename="package://yam_arm_description/meshes/converted_model2__7_808080ff.obj"/>
      </geometry>
    </visual>
    <collision name="left_model2__7_collision">
      <origin rpy="-2.87879006743723 1.4720957652931421 1.6013719605643306" xyz="-0.007710009148021196 -0.03486048010433765 0.0347071645682882"/>
      <geometry>
        <mesh filename="package://yam_arm_description/meshes/converted_model2__7_808080ff.obj"/>
      </geometry>
    </collision>
    <visual name="left_model2__8">
      <origin rpy="1.5707945314613085 0.0026832997041226214 -1.570809065297576" xyz="-0.1206720859561709 -0.06001334031535149 5.408345552423209e-07"/>
      <geometry>
        <mesh filename="package://yam_arm_description/meshes/converted_model2__8_808080ff.obj"/>
      </geometry>
    </visual>
    <collision name="left_model2__8_collision">
      <origin rpy="1.5707945314613085 0.0026832997041226214 -1.570809065297576" xyz="-0.1206720859561709 -0.06001334031535149 5.408345552423209e-07"/>
      <geometry>
        <mesh filename="package://yam_arm_description/meshes/converted_model2__8_808080ff.obj"/>
      </geometry>
    </collision>
    <visual name="left_model2__9">
      <origin rpy="0.28836143122615043 1.443690062944695 -1.515041718980295" xyz="-0.008240431625057998 -0.03737256683266851 -0.033699619180835645"/>
      <geometry>
        <mesh filename="package://yam_arm_description/meshes/converted_model2__9_808080ff.obj"/>
      </geometry>
    </visual>
    <collision name="left_model2__9_collision">
      <origin rpy="0.28836143122615043 1.443690062944695 -1.515041718980295" xyz="-0.008240431625057998 -0.03737256683266851 -0.033699619180835645"/>
      <geometry>
        <mesh filename="package://yam_arm_description/meshes/converted_model2__9_808080ff.obj"/>
      </geometry>
    </collision>
  </link>
  <link name="left_joint3_link">
    <inertial>
      <origin rpy="0.0 0.0 0.0" xyz="0.0 0.0 0.0"/>
      <mass value="0.001"/>
      <inertia ixx="1e-09" ixy="0" ixz="0" iyy="1e-09" iyz="0" izz="1e-09"/>
    </inertial>
  </link>
  <joint name="left_joint3" type="revolute">
    <parent link="left_link_2"/>
    <child link="left_joint3_link"/>
    <origin rpy="3.141592653589793 0.0 0.0" xyz="0.264 0.0 0.0"/>
    <axis xyz="0.0 0.0 1.0"/>
    <limit effort="300" lower="-1.0e-03" upper="3.66519" velocity="100"/>
  </joint>
  <joint name="left_joint3_offset" type="fixed">
    <parent link="left_joint3_link"/>
    <child link="left_link_3"/>
    <origin rpy="0.0 0.0 0.0" xyz="-0.0 -0.0 -0.0"/>
  </joint>
  <!-- Link 4 -->
  <link name="left_link_4">
    <inertial>
      <origin rpy="1.5707963267948966 0.0 -0.6801532411309218" xyz="-0.0769778 -0.0527104 0.000154878"/>
      <mass value="0.463511"/>
      <inertia ixx="0.000791532" ixy="0" ixz="0" iyy="0.000744733" iyz="0" izz="0.000282116"/>
    </inertial>
    <visual name="left_model2__10">
      <origin rpy="1.5394854457020648 0.021662003917252814 -0.7117475435376935" xyz="-0.046776068687813616 -0.038270471745625256 -0.0008915243508352188"/>
      <geometry>
        <mesh filename="package://yam_arm_description/meshes/converted_model2__10_808080ff.obj"/>
      </geometry>
    </visual>
    <collision name="left_model2__10_collision">
      <origin rpy="1.5394854457020648 0.021662003917252814 -0.7117475435376935" xyz="-0.046776068687813616 -0.038270471745625256 -0.0008915243508352188"/>
      <geometry>
        <mesh filename="package://yam_arm_description/meshes/converted_model2__10_808080ff.obj"/>
      </geometry>
    </collision>
  </link>
  <link name="left_joint4_link">
    <inertial>
      <origin rpy="0.0 0.0 0.0" xyz="0.0 0.0 0.0"/>
      <mass value="0.001"/>
      <inertia ixx="1e-09" ixy="0" ixz="0" iyy="1e-09" iyz="0" izz="1e-09"/>
    </inertial>
  </link>
  <joint name="left_joint4" type="revolute">
    <parent link="left_link_3"/>
    <child link="left_joint4_link"/>
    <origin rpy="0.0 0.0 0.0" xyz="-0.245 -0.06 0.0"/>
    <axis xyz="0.0 0.0 1.0"/>
    <limit effort="100" lower="-1.5708" upper="1.5708" velocity="100"/>
  </joint>
  <joint name="left_joint4_offset" type="fixed">
    <parent link="left_joint4_link"/>
    <child link="left_link_4"/>
    <origin rpy="0.0 0.0 0.0" xyz="-0.0 -0.0 -0.0"/>
  </joint>
  <!-- Link 5 -->
  <link name="left_link_5">
    <inertial>
      <origin rpy="0.0 0.0 0.0" xyz="3.64861e-05 0.00025665 0.0353526"/>
      <mass value="0.350962"/>
      <inertia ixx="0.000197802" ixy="0" ixz="0" iyy="0.0001775" iyz="0" izz="0.000147402"/>
    </inertial>
    <visual name="left_model2__11">
      <origin rpy="2.67318045036048 0.0016544870659682687 -0.01152938218496731" xyz="5.815639855540116e-05 -0.0005553836621680353 0.03206235288381598"/>
      <geometry>
        <mesh filename="package://yam_arm_description/meshes/converted_model2__11_808080ff.obj"/>
      </geometry>
    </visual>
    <collision name="left_model2__11_collision">
      <origin rpy="2.67318045036048 0.0016544870659682687 -0.01152938218496731" xyz="5.815639855540116e-05 -0.0005553836621680353 0.03206235288381598"/>
      <geometry>
        <mesh filename="package://yam_arm_description/meshes/converted_model2__11_808080ff.obj"/>
      </geometry>
    </collision>
  </link>
  <link name="left_joint5_link">
    <inertial>
      <origin rpy="0.0 0.0 0.0" xyz="0.0 0.0 0.0"/>
      <mass value="0.001"/>
      <inertia ixx="1e-09" ixy="0" ixz="0" iyy="1e-09" iyz="0" izz="1e-09"/>
    </inertial>
  </link>
  <joint name="left_joint5" type="revolute">
    <parent link="left_link_4"/>
    <child link="left_joint5_link"/>
    <origin rpy="-1.5707963267948966 1.5707963267948966 0.0" xyz="-0.074 -0.0395 2.5e-05"/>
    <axis xyz="0.0 0.0 1.0"/>
    <limit effort="100" lower="-1.5708" upper="1.5708" velocity="100"/>
  </joint>
  <joint name="left_joint5_offset" type="fixed">
    <parent link="left_joint5_link"/>
    <child link="left_link_5"/>
    <origin rpy="0.0 0.0 0.0" xyz="-0.0 -0.0 -0.0"/>
  </joint>
  <!-- Link 6 -->
  <link name="left_link_6">
    <inertial>
      <origin rpy="1.5707963267948963 0.0 0.0" xyz="-0.000217767 7.37059e-05 0.0270545"/>
      <mass value="0.367476"/>
      <inertia ixx="0.000265958" ixy="0" ixz="0" iyy="0.000242686" iyz="0" izz="0.000227409"/>
    </inertial>
    <visual name="left_model2__12">
      <origin rpy="-1.7453668887584697 1.565490971850807 -1.9699125405676954" xyz="8.788302043375991e-05 0.0001190912220788709 0.05116721790419726"/>
      <geometry>
        <mesh filename="package://yam_arm_description/meshes/converted_model2__12_808080ff.obj"/>
      </geometry>
    </visual>
    <collision name="left_model2__12_collision">
      <origin rpy="-1.7453668887584697 1.565490971850807 -1.9699125405676954" xyz="8.788302043375991e-05 0.0001190912220788709 0.05116721790419726"/>
      <geometry>
        <mesh filename="package://yam_arm_description/meshes/converted_model2__12_808080ff.obj"/>
      </geometry>
    </collision>
    <visual name="left_model2__13">
      <origin rpy="-1.5799559470247646 0.8170286688385331 -0.14641337505452354" xyz="-0.00017825474995774047 1.6195054943213272e-05 0.03422382038141725"/>
      <geometry>
        <mesh filename="package://yam_arm_description/meshes/converted_model2__13_808080ff.obj"/>
      </geometry>
    </visual>
    <collision name="left_model2__13_collision">
      <origin rpy="-1.5799559470247646 0.8170286688385331 -0.14641337505452354" xyz="-0.00017825474995774047 1.6195054943213272e-05 0.03422382038141725"/>
      <geometry>
        <mesh filename="package://yam_arm_description/meshes/converted_model2__13_808080ff.obj"/>
      </geometry>
    </collision>
  </link>
  <link name="left_joint6_link">
    <inertial>
      <origin rpy="0.0 0.0 0.0" xyz="0.0 0.0 0.0"/>
      <mass value="0.001"/>
      <inertia ixx="1e-09" ixy="0" ixz="0" iyy="1e-09" iyz="0" izz="1e-09"/>
    </inertial>
  </link>
  <joint name="left_joint6" type="revolute">
    <parent link="left_link_5"/>
    <child link="left_joint6_link"/>
    <origin rpy="-1.5707963267948963 0.0 0.0" xyz="0.0 0.0353 0.0395"/>
    <axis xyz="0.0 0.0 1.0"/>
    <limit effort="100" lower="-2.0944" upper="2.0944" velocity="100"/>
  </joint>
  <joint name="left_joint6_offset" type="fixed">
    <parent link="left_joint6_link"/>
    <child link="left_link_6"/>
    <origin rpy="0.0 0.0 0.0" xyz="-0.0 -0.0 -0.0"/>
  </joint>
  <!-- Gripper: Left Finger -->
  <link name="left_link_left_finger">
    <inertial>
      <origin rpy="1.401155911297378 -0.506095322833723 -0.42940521230428" xyz="-0.0192995 -0.0365902 0.039774"/>
      <mass value="0.118"/>
      <inertia ixx="0.000159084" ixy="0" ixz="0" iyy="0.000154909" iyz="0" izz="4.63655e-05"/>
    </inertial>
    <visual name="left_model2__14">
      <origin rpy="1.2436149090470108 -1.3351755324428634 3.1192068678405445" xyz="-0.02621919095860112 -0.050961301789609365 0.04847966761952425"/>
      <geometry>
        <mesh filename="package://yam_arm_description/meshes/converted_model2__14_808080ff.obj"/>
      </geometry>
    </visual>
    <collision name="left_model2__14_collision">
      <origin rpy="1.2436149090470108 -1.3351755324428634 3.1192068678405445" xyz="-0.02621919095860112 -0.050961301789609365 0.04847966761952425"/>
      <geometry>
        <mesh filename="package://yam_arm_description/meshes/converted_model2__14_808080ff.obj"/>
      </geometry>
    </collision>
    <visual name="left_model2__15">
      <origin rpy="-0.08499655397451025 -0.08210615684708134 0.012014286826329146" xyz="-0.0018267628293356375 -0.014013453565219658 0.02860778296204746"/>
      <geometry>
        <mesh filename="package://yam_arm_description/meshes/converted_model2__15_808080ff.obj"/>
      </geometry>
    </visual>
    <collision name="left_model2__15_collision">
      <origin rpy="-0.08499655397451025 -0.08210615684708134 0.012014286826329146" xyz="-0.0018267628293356375 -0.014013453565219658 0.02860778296204746"/>
      <geometry>
        <mesh filename="package://yam_arm_description/meshes/converted_model2__15_808080ff.obj"/>
      </geometry>
    </collision>
  </link>
  <link name="left_left_finger_link">
    <inertial>
      <origin rpy="0.0 0.0 0.0" xyz="0.0 0.0 0.0"/>
      <mass value="0.001"/>
      <inertia ixx="1e-09" ixy="0" ixz="0" iyy="1e-09" iyz="0" izz="1e-09"/>
    </inertial>
  </link>
  <joint name="left_left_finger" type="prismatic">
    <parent link="left_link_6"/>
    <child link="left_left_finger_link"/>
    <origin rpy="-0.0 1.5707963267948966 0.0" xyz="-0.037 0.0392 0.0605"/>
    <axis xyz="0.0 0.0 1.0"/>
    <limit effort="100" lower="-0.00205" upper="0.037524" velocity="100"/>
  </joint>
  <joint name="left_left_finger_offset" type="fixed">
    <parent link="left_left_finger_link"/>
    <child link="left_link_left_finger"/>
    <origin rpy="0.0 0.0 0.0" xyz="-0.0 -0.0 -0.0"/>
  </joint>
  <link name="left_lf_rot">
    <inertial>
      <origin rpy="2.03719733945046 0.34503462898803194 1.5781769326774222" xyz="-0.008421052631578949 -0.015789473684210527 0.020421052631578947"/>
      <mass value="0.039793506945470715"/>
      <inertia ixx="2.3910376870188726e-05" ixy="0" ixz="0" iyy="2.0730203360923295e-05" iyz="0" izz="5.660176249101842e-06"/>
    </inertial>
  </link>
  <joint name="left_link_left_finger2lf_rot_fixed" type="fixed">
    <parent link="left_link_left_finger"/>
    <child link="left_lf_rot"/>
    <origin rpy="-1.5707963267948966 0.0 1.5707963267948966" xyz="0.0 -0.0392 0.037"/>
  </joint>
  <link name="left_lf_down">
    <inertial>
      <origin rpy="0.25192924677866 0.2603701692584921 1.7911531458129852" xyz="0.004865675005941529 -0.012786258560154471 0.029346031921652322"/>
      <mass value="0.02077574023677297"/>
      <inertia ixx="1.5767067212852193e-05" ixy="0" ixz="0" iyy="1.3071054583294231e-05" iyz="0" izz="3.94367471938606e-06"/>
    </inertial>
  </link>
  <joint name="left_lf_rot2lf_down_fixed" type="fixed">
    <parent link="left_lf_rot"/>
    <child link="left_lf_down"/>
    <origin rpy="0.0 0.0 0.0" xyz="-0.044 0.0 0.0"/>
  </joint>
  <!-- Gripper: Right Finger -->
  <link name="left_link_right_finger">
    <inertial>
      <origin rpy="-1.401155911297378 0.506095322833723 -0.42940521230428" xyz="-0.0192995 0.0365902 -0.039774"/>
      <mass value="0.118"/>
      <inertia ixx="0.000159084" ixy="0" ixz="0" iyy="0.000154909" iyz="0" izz="4.63655e-05"/>
    </inertial>
    <visual name="left_model2__16">
      <origin rpy="-0.08499624911644794 0.08210615585822456 -0.012014239544932078" xyz="-0.001826763203738313 0.014013021507929144 -0.02860778467768097"/>
      <geometry>
        <mesh filename="package://yam_arm_description/meshes/converted_model2__16_808080ff.obj"/>
      </geometry>
    </visual>
    <collision name="left_model2__16_collision">
      <origin rpy="-0.08499624911644794 0.08210615585822456 -0.012014239544932078" xyz="-0.001826763203738313 0.014013021507929144 -0.02860778467768097"/>
      <geometry>
        <mesh filename="package://yam_arm_description/meshes/converted_model2__16_808080ff.obj"/>
      </geometry>
    </collision>
    <visual name="left_model2__17">
      <origin rpy="-1.8906094630983066 -1.338715519977303 -0.013733131456833558" xyz="-0.026152342123741346 0.026813733867866105 -0.04844908896546901"/>
      <geometry>
        <mesh filename="package://yam_arm_description/meshes/converted_model2__17_808080ff.obj"/>
      </geometry>
    </visual>
    <collision name="left_model2__17_collision">
      <origin rpy="-1.8906094630983066 -1.338715519977303 -0.013733131456833558" xyz="-0.026152342123741346 0.026813733867866105 -0.04844908896546901"/>
      <geometry>
        <mesh filename="package://yam_arm_description/meshes/converted_model2__17_808080ff.obj"/>
      </geometry>
    </collision>
  </link>
  <link name="left_right_finger_link">
    <inertial>
      <origin rpy="0.0 0.0 0.0" xyz="0.0 0.0 0.0"/>
      <mass value="0.001"/>
      <inertia ixx="1e-09" ixy="0" ixz="0" iyy="1e-09" iyz="0" izz="1e-09"/>
    </inertial>
  </link>
  <joint name="left_right_finger" type="prismatic">
    <parent link="left_link_6"/>
    <child link="left_right_finger_link"/>
    <origin rpy="-0.0 1.5707963267948966 0.0" xyz="0.037 -0.0392 0.0605"/>
    <axis xyz="0.0 0.0 1.0"/>
    <limit effort="100" lower="-0.037524" upper="0.00205" velocity="100"/>
    <mimic joint="left_left_finger" multiplier="-1" offset="0"/>
  </joint>
  <joint name="left_right_finger_offset" type="fixed">
    <parent link="left_right_finger_link"/>
    <child link="left_link_right_finger"/>
    <origin rpy="0.0 0.0 0.0" xyz="-0.0 -0.0 -0.0"/>
  </joint>
  <link name="left_rf_rot">
    <inertial>
      <origin rpy="1.1043953141393332 0.34503462898803194 1.563415720912371" xyz="0.008421052631578949 -0.015789473684210527 0.020421052631578947"/>
      <mass value="0.039793506945470715"/>
      <inertia ixx="2.3910376870188726e-05" ixy="0" ixz="0" iyy="2.0730203360923295e-05" iyz="0" izz="5.660176249101842e-06"/>
    </inertial>
  </link>
  <joint name="left_link_right_finger2rf_rot_fixed" type="fixed">
    <parent link="left_link_right_finger"/>
    <child link="left_rf_rot"/>
    <origin rpy="1.5707963267948966 0.0 -1.5707963267948966" xyz="0.0 0.0392 -0.037"/>
  </joint>
  <link name="left_rf_down">
    <inertial>
      <origin rpy="-0.25192924677866 0.2603701692584921 1.3504395077768079" xyz="-0.004865675005941529 -0.012786258560154471 0.029346031921652322"/>
      <mass value="0.02077574023677297"/>
      <inertia ixx="1.5767067212852193e-05" ixy="0" ixz="0" iyy="1.3071054583294231e-05" iyz="0" izz="3.94367471938606e-06"/>
    </inertial>
  </link>
  <joint name="left_rf_rot2rf_down_fixed" type="fixed">
    <parent link="left_rf_rot"/>
    <child link="left_rf_down"/>
    <origin rpy="0.0 0.0 0.0" xyz="0.044 0.0 0.0"/>
  </joint>
  <link name="left_camera_support">
    <inertial>
      <origin rpy="0.0 0.0 0.0" xyz="0.0 0.0 0.0"/>
      <mass value="0.1"/>
      <inertia ixx="0.0001" ixy="0" ixz="0" iyy="0.0001" iyz="0" izz="0.0001"/>
    </inertial>
    <visual name="left_camera_support_visual">
      <origin rpy="0.0 0.0 0.0" xyz="0.0 0.0 0.0"/>
      <geometry>
        <mesh filename="package://yam_arm_description/meshes/camera_support.stl"/>
      </geometry>
    </visual>
    <collision name="left_camera_support_collision">
      <origin rpy="0.0 0.0 0.0" xyz="0.0 0.0 0.0"/>
      <geometry>
        <mesh filename="package://yam_arm_description/meshes/camera_support.stl"/>
      </geometry>
    </collision>
  </link>
  <joint name="left_link_6_to_camera_support_fixed" type="fixed">
    <parent link="left_link_6"/>
    <child link="left_camera_support"/>
    <origin rpy="1.5708 1.5708 3.14159" xyz="-0.02618 0.04089 0.05052"/>
  </joint>
  <link name="left_d435">
    <inertial>
      <origin rpy="0.0 0.0 0.0" xyz="0.0 0.0 0.0"/>
      <mass value="0.072"/>
      <inertia ixx="0.0001" ixy="0" ixz="0" iyy="0.0001" iyz="0" izz="0.0001"/>
    </inertial>
    <visual name="left_d435_visual">
      <origin rpy="0.0 0.0 0.0" xyz="0.0 0.0 0.0"/>
      <geometry>
        <mesh filename="package://yam_arm_description/meshes/D435.obj"/>
      </geometry>
    </visual>
    <collision name="left_d435_collision">
      <origin rpy="0.0 0.0 0.0" xyz="0.0 0.0 0.0"/>
      <geometry>
        <mesh filename="package://yam_arm_description/meshes/D435.obj"/>
      </geometry>
    </collision>
  </link>
  <joint name="left_camera_support2d435_fixed" type="fixed">
    <parent link="left_camera_support"/>
    <child link="left_d435"/>
    <origin rpy="2.6180 0.0 -1.5708" xyz="-0.03014 0.00604 0.06023"/>
  </joint>
  <!-- Arm base link -->
  <link name="right_arm">
    <inertial>
      <origin rpy="0.0 0.0 0.0" xyz="0.0 0.0 0.026"/>
      <mass value="0.21895644158459424"/>
      <inertia ixx="0.00013879124248906134" ixy="0" ixz="0" iyy="0.00013879124248906134" iyz="0" izz="0.00010282878735692499"/>
    </inertial>
    <visual name="right_model2">
      <origin rpy="1.5701130102263443 0.005344186766801151 -3.1414365496107033" xyz="-2.0738360577213484e-05 2.041311002275178e-05 0.01154286287615687"/>
      <geometry>
        <mesh filename="package://yam_arm_description/meshes/converted_model2_808080ff.obj"/>
      </geometry>
    </visual>
    <collision name="right_model2_collision">
      <origin rpy="1.5701130102263443 0.005344186766801151 -3.1414365496107033" xyz="-2.0738360577213484e-05 2.041311002275178e-05 0.01154286287615687"/>
      <geometry>
        <mesh filename="package://yam_arm_description/meshes/converted_model2_808080ff.obj"/>
      </geometry>
    </collision>
  </link>
  <joint name="right_parent2arm_fixed" type="fixed">
    <parent link="base"/>
    <child link="right_arm"/>
    <origin rpy="0.0 0.0 0.0" xyz="0.0 -0.305 1.0"/>
  </joint>
  <!-- Link 1 -->
  <link name="right_link_1">
    <inertial>
      <origin rpy="1.6743480392523338 -0.6015439689011491 1.5666873963753192" xyz="-0.00192861 -0.00795735 0.0208176"/>
      <mass value="0.12415"/>
      <inertia ixx="0.000180751" ixy="0" ixz="0" iyy="0.000145532" iyz="0" izz="5.89179e-05"/>
    </inertial>
    <visual name="right_model2__2">
      <origin rpy="1.5650454550240567 -0.6317582807873867 1.5710673633815686" xyz="0.0007117901440024366 -0.008267794027987337 0.022250179687008112"/>
      <geometry>
        <mesh filename="package://yam_arm_description/meshes/converted_model2__2_808080ff.obj"/>
      </geometry>
    </visual>
    <collision name="right_model2__2_collision">
      <origin rpy="1.5650454550240567 -0.6317582807873867 1.5710673633815686" xyz="0.0007117901440024366 -0.008267794027987337 0.022250179687008112"/>
      <geometry>
        <mesh filename="package://yam_arm_description/meshes/converted_model2__2_808080ff.obj"/>
      </geometry>
    </collision>
  </link>
  <link name="right_joint1_link">
    <inertial>
      <origin rpy="0.0 0.0 0.0" xyz="0.0 0.0 0.0"/>
      <mass value="0.001"/>
      <inertia ixx="1e-09" ixy="0" ixz="0" iyy="1e-09" iyz="0" izz="1e-09"/>
    </inertial>
  </link>
  <joint name="right_joint1" type="revolute">
    <parent link="right_arm"/>
    <child link="right_joint1_link"/>
    <origin rpy="0.0 0.0 1.5707963267948963" xyz="0.0 0.0 0.0631"/>
    <axis xyz="0.0 0.0 1.0"/>
    <limit effort="100" lower="-2.61799" upper="3.05433" velocity="100"/>
  </joint>
  <joint name="right_joint1_offset" type="fixed">
    <parent link="right_joint1_link"/>
    <child link="right_link_1"/>
    <origin rpy="0.0 0.0 0.0" xyz="-0.0 -0.0 -0.0"/>
  </joint>
  <!-- Link 2 -->
  <link name="right_link_2">
    <inertial>
      <origin rpy="1.5707963267948966 0.0 1.5707963267948966" xyz="0.132008 2.10599e-06 0.000293073"/>
      <mass value="1.24434"/>
      <inertia ixx="0.0121902" ixy="0" ixz="0" iyy="0.0121318" iyz="0" izz="0.000683304"/>
    </inertial>
    <visual name="right_model2__3">
      <origin rpy="0.0012886015838013758 0.0 1.5707963267948966" xyz="0.26007948449650414 2.5977632368834325e-07 0.00022869283697025413"/>
      <geometry>
        <mesh filename="package://yam_arm_description/meshes/converted_model2__3_808080ff.obj"/>
      </geometry>
    </visual>
    <collision name="right_model2__3_collision">
      <origin rpy="0.0012886015838013758 0.0 1.5707963267948966" xyz="0.26007948449650414 2.5977632368834325e-07 0.00022869283697025413"/>
      <geometry>
        <mesh filename="package://yam_arm_description/meshes/converted_model2__3_808080ff.obj"/>
      </geometry>
    </collision>
    <visual name="right_model2__4">
      <origin rpy="-0.0012886020855807743 0.0 1.5707963267948966" xyz="0.003920561027152974 2.5977629421192194e-07 0.00022869282878015162"/>
      <geometry>
        <mesh filename="package://yam_arm_description/meshes/converted_model2__4_808080ff.obj"/>
      </geometry>
    </visual>
    <collision name="right_model2__4_collision">
      <origin rpy="-0.0012886020855807743 0.0 1.5707963267948966" xyz="0.003920561027152974 2.5977629421192194e-07 0.00022869282878015162"/>
      <geometry>
        <mesh filename="package://yam_arm_description/meshes/converted_model2__4_808080ff.obj"/>
      </geometry>
    </collision>
    <visual name="right_model2__5">
      <origin rpy="1.5720341600620127 -1.5679213575591051 -1.5720413321413815" xyz="0.1320117461361114 -1.306943646950387e-05 9.079293692478702e-08"/>
      <geometry>
        <mesh filename="package://yam_arm_description/meshes/converted_model2__5_808080ff.obj"/>
      </geometry>
    </visual>
    <collision name="right_model2__5_collision">
      <origin rpy="1.5720341600620127 -1.5679213575591051 -1.5720413321413815" xyz="0.1320117461361114 -1.306943646950387e-05 9.079293692478702e-08"/>
      <geometry>
        <mesh filename="package://yam_arm_description/meshes/converted_model2__5_808080ff.obj"/>
      </geometry>
    </collision>
  </link>
  <link name="right_joint2_link">
    <inertial>
      <origin rpy="0.0 0.0 0.0" xyz="0.0 0.0 0.0"/>
      <mass value="0.001"/>
      <inertia ixx="1e-09" ixy="0" ixz="0" iyy="1e-09" iyz="0" izz="1e-09"/>
    </inertial>
  </link>
  <joint name="right_joint2" type="revolute">
    <parent link="right_link_1"/>
    <child link="right_joint2_link"/>
    <origin rpy="1.5707963267948966 0.0 1.5707963267948966" xyz="2.5e-05 -0.02 0.0409"/>
    <axis xyz="0.0 0.0 1.0"/>
    <limit effort="300" lower="-1.0e-03" upper="3.66519" velocity="100"/>
  </joint>
  <joint name="right_joint2_offset" type="fixed">
    <parent link="right_joint2_link"/>
    <child link="right_link_2"/>
    <origin rpy="0.0 0.0 0.0" xyz="-0.0 -0.0 -0.0"/>
  </joint>
  <!-- Link 3 -->
  <link name="right_link_3">
    <inertial>
      <origin rpy="1.5707963267948966 0.0 1.5707963267948966" xyz="-0.121816 -0.054846 -0.000111108"/>
      <mass value="0.853698"/>
      <inertia ixx="0.00699732" ixy="0" ixz="0" iyy="0.00696112" iyz="0" izz="0.000788244"/>
    </inertial>
    <visual name="right_model2__6">
      <origin rpy="3.0364915071378875 0.0 -1.5707963267948968" xyz="-0.24063976713274154 -0.059999782142154706 -0.003760273578300405"/>
      <geometry>
        <mesh filename="package://yam_arm_description/meshes/converted_model2__6_808080ff.obj"/>
      </geometry>
    </visual>
    <collision name="right_model2__6_collision">
      <origin rpy="3.0364915071378875 0.0 -1.5707963267948968" xyz="-0.24063976713274154 -0.059999782142154706 -0.003760273578300405"/>
      <geometry>
        <mesh filename="package://yam_arm_description/meshes/converted_model2__6_808080ff.obj"/>
      </geometry>
    </collision>
    <visual name="right_model2__7">
      <origin rpy="-2.87879006743723 1.4720957652931421 1.6013719605643306" xyz="-0.007710009148021196 -0.03486048010433765 0.0347071645682882"/>
      <geometry>
        <mesh filename="package://yam_arm_description/meshes/converted_model2__7_808080ff.obj"/>
      </geometry>
    </visual>
    <collision name="right_model2__7_collision">
      <origin rpy="-2.87879006743723 1.4720957652931421 1.6013719605643306" xyz="-0.007710009148021196 -0.03486048010433765 0.0347071645682882"/>
      <geometry>
        <mesh filename="package://yam_arm_description/meshes/converted_model2__7_808080ff.obj"/>
      </geometry>
    </collision>
    <visual name="right_model2__8">
      <origin rpy="1.5707945314613085 0.0026832997041226214 -1.570809065297576" xyz="-0.1206720859561709 -0.06001334031535149 5.408345552423209e-07"/>
      <geometry>
        <mesh filename="package://yam_arm_description/meshes/converted_model2__8_808080ff.obj"/>
      </geometry>
    </visual>
    <collision name="right_model2__8_collision">
      <origin rpy="1.5707945314613085 0.0026832997041226214 -1.570809065297576" xyz="-0.1206720859561709 -0.06001334031535149 5.408345552423209e-07"/>
      <geometry>
        <mesh filename="package://yam_arm_description/meshes/converted_model2__8_808080ff.obj"/>
      </geometry>
    </collision>
    <visual name="right_model2__9">
      <origin rpy="0.28836143122615043 1.443690062944695 -1.515041718980295" xyz="-0.008240431625057998 -0.03737256683266851 -0.033699619180835645"/>
      <geometry>
        <mesh filename="package://yam_arm_description/meshes/converted_model2__9_808080ff.obj"/>
      </geometry>
    </visual>
    <collision name="right_model2__9_collision">
      <origin rpy="0.28836143122615043 1.443690062944695 -1.515041718980295" xyz="-0.008240431625057998 -0.03737256683266851 -0.033699619180835645"/>
      <geometry>
        <mesh filename="package://yam_arm_description/meshes/converted_model2__9_808080ff.obj"/>
      </geometry>
    </collision>
  </link>
  <link name="right_joint3_link">
    <inertial>
      <origin rpy="0.0 0.0 0.0" xyz="0.0 0.0 0.0"/>
      <mass value="0.001"/>
      <inertia ixx="1e-09" ixy="0" ixz="0" iyy="1e-09" iyz="0" izz="1e-09"/>
    </inertial>
  </link>
  <joint name="right_joint3" type="revolute">
    <parent link="right_link_2"/>
    <child link="right_joint3_link"/>
    <origin rpy="3.141592653589793 0.0 0.0" xyz="0.264 0.0 0.0"/>
    <axis xyz="0.0 0.0 1.0"/>
    <limit effort="300" lower="-1.0e-03" upper="3.66519" velocity="100"/>
  </joint>
  <joint name="right_joint3_offset" type="fixed">
    <parent link="right_joint3_link"/>
    <child link="right_link_3"/>
    <origin rpy="0.0 0.0 0.0" xyz="-0.0 -0.0 -0.0"/>
  </joint>
  <!-- Link 4 -->
  <link name="right_link_4">
    <inertial>
      <origin rpy="1.5707963267948966 0.0 -0.6801532411309218" xyz="-0.0769778 -0.0527104 0.000154878"/>
      <mass value="0.463511"/>
      <inertia ixx="0.000791532" ixy="0" ixz="0" iyy="0.000744733" iyz="0" izz="0.000282116"/>
    </inertial>
    <visual name="right_model2__10">
      <origin rpy="1.5394854457020648 0.021662003917252814 -0.7117475435376935" xyz="-0.046776068687813616 -0.038270471745625256 -0.0008915243508352188"/>
      <geometry>
        <mesh filename="package://yam_arm_description/meshes/converted_model2__10_808080ff.obj"/>
      </geometry>
    </visual>
    <collision name="right_model2__10_collision">
      <origin rpy="1.5394854457020648 0.021662003917252814 -0.7117475435376935" xyz="-0.046776068687813616 -0.038270471745625256 -0.0008915243508352188"/>
      <geometry>
        <mesh filename="package://yam_arm_description/meshes/converted_model2__10_808080ff.obj"/>
      </geometry>
    </collision>
  </link>
  <link name="right_joint4_link">
    <inertial>
      <origin rpy="0.0 0.0 0.0" xyz="0.0 0.0 0.0"/>
      <mass value="0.001"/>
      <inertia ixx="1e-09" ixy="0" ixz="0" iyy="1e-09" iyz="0" izz="1e-09"/>
    </inertial>
  </link>
  <joint name="right_joint4" type="revolute">
    <parent link="right_link_3"/>
    <child link="right_joint4_link"/>
    <origin rpy="0.0 0.0 0.0" xyz="-0.245 -0.06 0.0"/>
    <axis xyz="0.0 0.0 1.0"/>
    <limit effort="100" lower="-1.5708" upper="1.5708" velocity="100"/>
  </joint>
  <joint name="right_joint4_offset" type="fixed">
    <parent link="right_joint4_link"/>
    <child link="right_link_4"/>
    <origin rpy="0.0 0.0 0.0" xyz="-0.0 -0.0 -0.0"/>
  </joint>
  <!-- Link 5 -->
  <link name="right_link_5">
    <inertial>
      <origin rpy="0.0 0.0 0.0" xyz="3.64861e-05 0.00025665 0.0353526"/>
      <mass value="0.350962"/>
      <inertia ixx="0.000197802" ixy="0" ixz="0" iyy="0.0001775" iyz="0" izz="0.000147402"/>
    </inertial>
    <visual name="right_model2__11">
      <origin rpy="2.67318045036048 0.0016544870659682687 -0.01152938218496731" xyz="5.815639855540116e-05 -0.0005553836621680353 0.03206235288381598"/>
      <geometry>
        <mesh filename="package://yam_arm_description/meshes/converted_model2__11_808080ff.obj"/>
      </geometry>
    </visual>
    <collision name="right_model2__11_collision">
      <origin rpy="2.67318045036048 0.0016544870659682687 -0.01152938218496731" xyz="5.815639855540116e-05 -0.0005553836621680353 0.03206235288381598"/>
      <geometry>
        <mesh filename="package://yam_arm_description/meshes/converted_model2__11_808080ff.obj"/>
      </geometry>
    </collision>
  </link>
  <link name="right_joint5_link">
    <inertial>
      <origin rpy="0.0 0.0 0.0" xyz="0.0 0.0 0.0"/>
      <mass value="0.001"/>
      <inertia ixx="1e-09" ixy="0" ixz="0" iyy="1e-09" iyz="0" izz="1e-09"/>
    </inertial>
  </link>
  <joint name="right_joint5" type="revolute">
    <parent link="right_link_4"/>
    <child link="right_joint5_link"/>
    <origin rpy="-1.5707963267948966 1.5707963267948966 0.0" xyz="-0.074 -0.0395 2.5e-05"/>
    <axis xyz="0.0 0.0 1.0"/>
    <limit effort="100" lower="-1.5708" upper="1.5708" velocity="100"/>
  </joint>
  <joint name="right_joint5_offset" type="fixed">
    <parent link="right_joint5_link"/>
    <child link="right_link_5"/>
    <origin rpy="0.0 0.0 0.0" xyz="-0.0 -0.0 -0.0"/>
  </joint>
  <!-- Link 6 -->
  <link name="right_link_6">
    <inertial>
      <origin rpy="1.5707963267948963 0.0 0.0" xyz="-0.000217767 7.37059e-05 0.0270545"/>
      <mass value="0.367476"/>
      <inertia ixx="0.000265958" ixy="0" ixz="0" iyy="0.000242686" iyz="0" izz="0.000227409"/>
    </inertial>
    <visual name="right_model2__12">
      <origin rpy="-1.7453668887584697 1.565490971850807 -1.9699125405676954" xyz="8.788302043375991e-05 0.0001190912220788709 0.05116721790419726"/>
      <geometry>
        <mesh filename="package://yam_arm_description/meshes/converted_model2__12_808080ff.obj"/>
      </geometry>
    </visual>
    <collision name="right_model2__12_collision">
      <origin rpy="-1.7453668887584697 1.565490971850807 -1.9699125405676954" xyz="8.788302043375991e-05 0.0001190912220788709 0.05116721790419726"/>
      <geometry>
        <mesh filename="package://yam_arm_description/meshes/converted_model2__12_808080ff.obj"/>
      </geometry>
    </collision>
    <visual name="right_model2__13">
      <origin rpy="-1.5799559470247646 0.8170286688385331 -0.14641337505452354" xyz="-0.00017825474995774047 1.6195054943213272e-05 0.03422382038141725"/>
      <geometry>
        <mesh filename="package://yam_arm_description/meshes/converted_model2__13_808080ff.obj"/>
      </geometry>
    </visual>
    <collision name="right_model2__13_collision">
      <origin rpy="-1.5799559470247646 0.8170286688385331 -0.14641337505452354" xyz="-0.00017825474995774047 1.6195054943213272e-05 0.03422382038141725"/>
      <geometry>
        <mesh filename="package://yam_arm_description/meshes/converted_model2__13_808080ff.obj"/>
      </geometry>
    </collision>
  </link>
  <link name="right_joint6_link">
    <inertial>
      <origin rpy="0.0 0.0 0.0" xyz="0.0 0.0 0.0"/>
      <mass value="0.001"/>
      <inertia ixx="1e-09" ixy="0" ixz="0" iyy="1e-09" iyz="0" izz="1e-09"/>
    </inertial>
  </link>
  <joint name="right_joint6" type="revolute">
    <parent link="right_link_5"/>
    <child link="right_joint6_link"/>
    <origin rpy="-1.5707963267948963 0.0 0.0" xyz="0.0 0.0353 0.0395"/>
    <axis xyz="0.0 0.0 1.0"/>
    <limit effort="100" lower="-2.0944" upper="2.0944" velocity="100"/>
  </joint>
  <joint name="right_joint6_offset" type="fixed">
    <parent link="right_joint6_link"/>
    <child link="right_link_6"/>
    <origin rpy="0.0 0.0 0.0" xyz="-0.0 -0.0 -0.0"/>
  </joint>
  <!-- Gripper: Left Finger -->
  <link name="right_link_left_finger">
    <inertial>
      <origin rpy="1.401155911297378 -0.506095322833723 -0.42940521230428" xyz="-0.0192995 -0.0365902 0.039774"/>
      <mass value="0.118"/>
      <inertia ixx="0.000159084" ixy="0" ixz="0" iyy="0.000154909" iyz="0" izz="4.63655e-05"/>
    </inertial>
    <visual name="right_model2__14">
      <origin rpy="1.2436149090470108 -1.3351755324428634 3.1192068678405445" xyz="-0.02621919095860112 -0.050961301789609365 0.04847966761952425"/>
      <geometry>
        <mesh filename="package://yam_arm_description/meshes/converted_model2__14_808080ff.obj"/>
      </geometry>
    </visual>
    <collision name="right_model2__14_collision">
      <origin rpy="1.2436149090470108 -1.3351755324428634 3.1192068678405445" xyz="-0.02621919095860112 -0.050961301789609365 0.04847966761952425"/>
      <geometry>
        <mesh filename="package://yam_arm_description/meshes/converted_model2__14_808080ff.obj"/>
      </geometry>
    </collision>
    <visual name="right_model2__15">
      <origin rpy="-0.08499655397451025 -0.08210615684708134 0.012014286826329146" xyz="-0.0018267628293356375 -0.014013453565219658 0.02860778296204746"/>
      <geometry>
        <mesh filename="package://yam_arm_description/meshes/converted_model2__15_808080ff.obj"/>
      </geometry>
    </visual>
    <collision name="right_model2__15_collision">
      <origin rpy="-0.08499655397451025 -0.08210615684708134 0.012014286826329146" xyz="-0.0018267628293356375 -0.014013453565219658 0.02860778296204746"/>
      <geometry>
        <mesh filename="package://yam_arm_description/meshes/converted_model2__15_808080ff.obj"/>
      </geometry>
    </collision>
  </link>
  <link name="right_left_finger_link">
    <inertial>
      <origin rpy="0.0 0.0 0.0" xyz="0.0 0.0 0.0"/>
      <mass value="0.001"/>
      <inertia ixx="1e-09" ixy="0" ixz="0" iyy="1e-09" iyz="0" izz="1e-09"/>
    </inertial>
  </link>
  <joint name="right_left_finger" type="prismatic">
    <parent link="right_link_6"/>
    <child link="right_left_finger_link"/>
    <origin rpy="-0.0 1.5707963267948966 0.0" xyz="-0.037 0.0392 0.0605"/>
    <axis xyz="0.0 0.0 1.0"/>
    <limit effort="100" lower="-0.00205" upper="0.037524" velocity="100"/>
  </joint>
  <joint name="right_left_finger_offset" type="fixed">
    <parent link="right_left_finger_link"/>
    <child link="right_link_left_finger"/>
    <origin rpy="0.0 0.0 0.0" xyz="-0.0 -0.0 -0.0"/>
  </joint>
  <link name="right_lf_rot">
    <inertial>
      <origin rpy="2.03719733945046 0.34503462898803194 1.5781769326774222" xyz="-0.008421052631578949 -0.015789473684210527 0.020421052631578947"/>
      <mass value="0.039793506945470715"/>
      <inertia ixx="2.3910376870188726e-05" ixy="0" ixz="0" iyy="2.0730203360923295e-05" iyz="0" izz="5.660176249101842e-06"/>
    </inertial>
  </link>
  <joint name="right_link_left_finger2lf_rot_fixed" type="fixed">
    <parent link="right_link_left_finger"/>
    <child link="right_lf_rot"/>
    <origin rpy="-1.5707963267948966 0.0 1.5707963267948966" xyz="0.0 -0.0392 0.037"/>
  </joint>
  <link name="right_lf_down">
    <inertial>
      <origin rpy="0.25192924677866 0.2603701692584921 1.7911531458129852" xyz="0.004865675005941529 -0.012786258560154471 0.029346031921652322"/>
      <mass value="0.02077574023677297"/>
      <inertia ixx="1.5767067212852193e-05" ixy="0" ixz="0" iyy="1.3071054583294231e-05" iyz="0" izz="3.94367471938606e-06"/>
    </inertial>
  </link>
  <joint name="right_lf_rot2lf_down_fixed" type="fixed">
    <parent link="right_lf_rot"/>
    <child link="right_lf_down"/>
    <origin rpy="0.0 0.0 0.0" xyz="-0.044 0.0 0.0"/>
  </joint>
  <!-- Gripper: Right Finger -->
  <link name="right_link_right_finger">
    <inertial>
      <origin rpy="-1.401155911297378 0.506095322833723 -0.42940521230428" xyz="-0.0192995 0.0365902 -0.039774"/>
      <mass value="0.118"/>
      <inertia ixx="0.000159084" ixy="0" ixz="0" iyy="0.000154909" iyz="0" izz="4.63655e-05"/>
    </inertial>
    <visual name="right_model2__16">
      <origin rpy="-0.08499624911644794 0.08210615585822456 -0.012014239544932078" xyz="-0.001826763203738313 0.014013021507929144 -0.02860778467768097"/>
      <geometry>
        <mesh filename="package://yam_arm_description/meshes/converted_model2__16_808080ff.obj"/>
      </geometry>
    </visual>
    <collision name="right_model2__16_collision">
      <origin rpy="-0.08499624911644794 0.08210615585822456 -0.012014239544932078" xyz="-0.001826763203738313 0.014013021507929144 -0.02860778467768097"/>
      <geometry>
        <mesh filename="package://yam_arm_description/meshes/converted_model2__16_808080ff.obj"/>
      </geometry>
    </collision>
    <visual name="right_model2__17">
      <origin rpy="-1.8906094630983066 -1.338715519977303 -0.013733131456833558" xyz="-0.026152342123741346 0.026813733867866105 -0.04844908896546901"/>
      <geometry>
        <mesh filename="package://yam_arm_description/meshes/converted_model2__17_808080ff.obj"/>
      </geometry>
    </visual>
    <collision name="right_model2__17_collision">
      <origin rpy="-1.8906094630983066 -1.338715519977303 -0.013733131456833558" xyz="-0.026152342123741346 0.026813733867866105 -0.04844908896546901"/>
      <geometry>
        <mesh filename="package://yam_arm_description/meshes/converted_model2__17_808080ff.obj"/>
      </geometry>
    </collision>
  </link>
  <link name="right_right_finger_link">
    <inertial>
      <origin rpy="0.0 0.0 0.0" xyz="0.0 0.0 0.0"/>
      <mass value="0.001"/>
      <inertia ixx="1e-09" ixy="0" ixz="0" iyy="1e-09" iyz="0" izz="1e-09"/>
    </inertial>
  </link>
  <joint name="right_right_finger" type="prismatic">
    <parent link="right_link_6"/>
    <child link="right_right_finger_link"/>
    <origin rpy="-0.0 1.5707963267948966 0.0" xyz="0.037 -0.0392 0.0605"/>
    <axis xyz="0.0 0.0 1.0"/>
    <limit effort="100" lower="-0.037524" upper="0.00205" velocity="100"/>
    <mimic joint="right_left_finger" multiplier="-1" offset="0"/>
  </joint>
  <joint name="right_right_finger_offset" type="fixed">
    <parent link="right_right_finger_link"/>
    <child link="right_link_right_finger"/>
    <origin rpy="0.0 0.0 0.0" xyz="-0.0 -0.0 -0.0"/>
  </joint>
  <link name="right_rf_rot">
    <inertial>
      <origin rpy="1.1043953141393332 0.34503462898803194 1.563415720912371" xyz="0.008421052631578949 -0.015789473684210527 0.020421052631578947"/>
      <mass value="0.039793506945470715"/>
      <inertia ixx="2.3910376870188726e-05" ixy="0" ixz="0" iyy="2.0730203360923295e-05" iyz="0" izz="5.660176249101842e-06"/>
    </inertial>
  </link>
  <joint name="right_link_right_finger2rf_rot_fixed" type="fixed">
    <parent link="right_link_right_finger"/>
    <child link="right_rf_rot"/>
    <origin rpy="1.5707963267948966 0.0 -1.5707963267948966" xyz="0.0 0.0392 -0.037"/>
  </joint>
  <link name="right_rf_down">
    <inertial>
      <origin rpy="-0.25192924677866 0.2603701692584921 1.3504395077768079" xyz="-0.004865675005941529 -0.012786258560154471 0.029346031921652322"/>
      <mass value="0.02077574023677297"/>
      <inertia ixx="1.5767067212852193e-05" ixy="0" ixz="0" iyy="1.3071054583294231e-05" iyz="0" izz="3.94367471938606e-06"/>
    </inertial>
  </link>
  <joint name="right_rf_rot2rf_down_fixed" type="fixed">
    <parent link="right_rf_rot"/>
    <child link="right_rf_down"/>
    <origin rpy="0.0 0.0 0.0" xyz="0.044 0.0 0.0"/>
  </joint>
  <link name="right_camera_support">
    <inertial>
      <origin rpy="0.0 0.0 0.0" xyz="0.0 0.0 0.0"/>
      <mass value="0.1"/>
      <inertia ixx="0.0001" ixy="0" ixz="0" iyy="0.0001" iyz="0" izz="0.0001"/>
    </inertial>
    <visual name="right_camera_support_visual">
      <origin rpy="0.0 0.0 0.0" xyz="0.0 0.0 0.0"/>
      <geometry>
        <mesh filename="package://yam_arm_description/meshes/camera_support.stl"/>
      </geometry>
    </visual>
    <collision name="right_camera_support_collision">
      <origin rpy="0.0 0.0 0.0" xyz="0.0 0.0 0.0"/>
      <geometry>
        <mesh filename="package://yam_arm_description/meshes/camera_support.stl"/>
      </geometry>
    </collision>
  </link>
  <joint name="right_link_6_to_camera_support_fixed" type="fixed">
    <parent link="right_link_6"/>
    <child link="right_camera_support"/>
    <origin rpy="1.5708 1.5708 3.14159" xyz="-0.02618 0.04089 0.05052"/>
  </joint>
  <link name="right_d435">
    <inertial>
      <origin rpy="0.0 0.0 0.0" xyz="0.0 0.0 0.0"/>
      <mass value="0.072"/>
      <inertia ixx="0.0001" ixy="0" ixz="0" iyy="0.0001" iyz="0" izz="0.0001"/>
    </inertial>
    <visual name="right_d435_visual">
      <origin rpy="0.0 0.0 0.0" xyz="0.0 0.0 0.0"/>
      <geometry>
        <mesh filename="package://yam_arm_description/meshes/D435.obj"/>
      </geometry>
    </visual>
    <collision name="right_d435_collision">
      <origin rpy="0.0 0.0 0.0" xyz="0.0 0.0 0.0"/>
      <geometry>
        <mesh filename="package://yam_arm_description/meshes/D435.obj"/>
      </geometry>
    </collision>
  </link>
  <joint name="right_camera_support2d435_fixed" type="fixed">
    <parent link="right_camera_support"/>
    <child link="right_d435"/>
    <origin rpy="2.6180 0.0 -1.5708" xyz="-0.03014 0.00604 0.06023"/>
  </joint>
</robot>
